Workbook

Sheet Coordenadas 
A1: Punto de Muestreos | B1: Tramos | C1: Abr | D1: Lalitud | E1: Longitud | F1: Altitud
A2: Desembocadura - Zaino | B2: Tramo bajo | C2: P1 | D2: 11°16'59.1" N | E2: 73°54'27.7" W | F2: 18
A3: Parte baja - Rio Piedra | B3: Tramo bajo | C3: P2 | D3: 11°16'39.4" N | E3: 73°55'45.2" W | F3: 54
A4: La Lisa | B4: Tramo medio | C4: P3 | D4: 11°13'46.7" N | E4: 74°01'23.1" W | F4: 427
A5: Bocatoma | B5: Tramo alto | C5: P4 | D5: 11°12'37.1" N | E5: 74°02'10.30" W | F5: 564
A6: Atinkana | B6: Tramo alto | C6: P5 | D6: 11°12'33.27'' N | E6: 74°02'46.71'' W | F6: 1000

Sheet Diccionario
A3: → ¿Cómo esta organizado el libro?
A5: Macroinv. | B5: Datos crudos de macroinvertebrados acuáticos
A6: Perifiton | B6: Datos de perifiton depurados (los datos originales estan en la nube carpeta del proyecto)
A7: Peces | B7: Datos crudos del componente peces
A8: IQR | B8: Datos de vegetación y propuesta de para la traducción del IQR a IIBveg
A11: → Código de Colores (Propuesta)
A13: IBI compuesto
A15: Puntaje IBIcomp | B15: Clase ecológica | C15: Código de color | D15: Descripción
A16: [0,0 - 0,2) | B16: Muy baja | D16: Muy pobre integridad biótica de las comunidades acuáticas que implica un estado ecológico muy malo del sitio de muestreo
A17: [0,2 - 0,4) | B17: Baja | D17: Pobre integridad biótica de las comunidades acuáticas que implica un estado ecológico malo del sitio de muestreo
A18: [0,4 - 0,6) | B18: Moderada | D18: Moderada integridad biótica de las comunidades acuáticas que implica un estado ecológico deficiente del sitio de muestreo
A19: [0,6 - 0,8) | B19: Alta | D19: Buena integridad biótica de las comunidades acuáticas que implica un estado ecológico bueno del sitio de muestreo
A20: [0,8 - 1,0] | B20: Muy alta | D20: Excelente integridad biótica de las comunidades acuáticas que implica un estado ecológico excelente del sitio de muestreo
A23: → Flujo de Trabajo Recomendado (Pinilla et al., 2014)
A25: 1. Tabulación de los datos
A26: 2. Listado de métricas ajustadas a la cuenca estudiada
A27: 3. Selección de las métricas que mejor describen la cuenca
A28: 4. Calcular las métricas para cada tramo y/o temporada climática
A29: 5. Calculo del IBI preliminar: cálculo del IBI por componente
A30: 6. Estandarización de la métrica por componente: escala de valor de las métricas sean comparables entre si y con los otros componentes del IBI
A31: 7. Delimitación del semanforo: los IBI por componente son comparables en escala de valor y se puede calcular el IBI compuesto
A32: 8. Comparación del valor del IBI calculado por tramo con las variables fisicoquímicas y otros datos de la cuenca para poder explicar el estado de la cuenca
A35: → Diccionario de Variables
A37: Nota: -Macro (Macroinvertebrados acuáticos) -IIBMA: índice de integridad biótica componente macroinvertebrados acuáticos -IIBPerif: índice de integridad biótica componente perifiton -IIBPeces: índice de integridad biótica componente peces -IIBVegRib: índice de integridad biótica componente vegetación de ribera -IIBComp: índice de integridad biótica compuesto
A45: Variable | B45: Componente | C45: Ecuación | D45: Definición
A46: % Chironomidae (%Chi) | B46: Macro | C46: %Chi=(N° indv. Chi/total indv.)*100 | D46: Porcentaje de taxones de la familia Chironomidae
A47: % Colectores (%CG) | B47: Macro | C47: %CG= (N° indv. CG /total indv.)*100 | D47: Porcentaje de taxones que se alimentan de materia orgánica particulada depositada en el sedimento
A48: % Depredadores (%Pr) | B48: Macro | C48: %Pr= (N° indv. Pr /total indv.)*100 | D48: Porcentaje de taxones que se alimentan de tejido animal vivo
A49: % Filtradores (%Ft) | B49: Macro | C49: %Ft= (N° indv. Ft /total indv.)*100 | D49: Porcentaje de taxones que se alimentan de materia orgánica particulada fina de la columna de agua
A50: % Fragmentadores (%Sh-dt) | B50: Macro | C50: %Sh-Dt= (N° indv. Sh-Dt /total indv.)*100 | D50: Porcentaje de taxones que trituran materia orgánica particulada gruesa
A51: % Raspador (Ras) | B51: Macro | C51: %Ras= (N° indv. Ras /total indv.)*100 | D51: Porcentaje de taxones que se alimentan de perifiton/ biopelícula
A52: %EPT | B52: Macro | C52: %EPT= (N° indv. EPT /total indv.)*100 | D52: Porcentaje de familias de los órdenes de Ephemeroptera, Plecoptera y Trichoptera encontrados
A53: Abundancia | B53: Macro, peces | C53: - | D53: Número de individuos por morfoespecies
A54: Abundancia total | B54: Macro, peces | C54: - | D54: Número total de individuos recolectados por tramo
A55: Alto perfil | B55: Perifiton | C55: - | D55: Gremio ecológico (Passy, 2007): contiene especies de talla más grande o que tienden a formar grandes colonias. Incluye a las formas erectas, filamentosas, ramificadas, en cadena, tuberiformes, pedunculadas y centrales coloniales
A56: Anotaciones | B56: Todos | C56: - | D56: Nota con respecto al dato, ya sea para verificar o buscar más información al respecto
... A93: Triturador (Tr) | B93: Macro | C93: - | D93: Taxones que trituran materia orgánica particulada gruesa de hojarasca y hojas vivas

Sheet Macroinv.
A1: Macroinvertebrados Acuáticos
A3: Localidad: | B3: Rio Piedra
D5: Coordenadas
A6: Fecha | B6: Tramo | C6: Sitio | D6: Lalitud | E6: Longitud | F6: Micro-Habitat | G6: Réplica | H6: Orden | I6: Familia / subfamilia | J6: Género | K6: Abundancia | L6: Abundancia relativa | M6: Grupos funcionales | N6: Puntaje BMWP/Col | O6: Anotaciones | Q6: Abundancia total
A7: 45625 | B7: Medio | C7: La Lisa | D7: 11°13'46,7" N | E7: 74°01'23,1" W | F7: Arena | G7: 2 | H7: Trichoptera | I7: Leptoceridae | J7: Atanatolica | K7: 1 | L7: =(K7/$Q$7)*100 -> 0.018975332 | M7: CG | N7: =IFERROR(INDEX(BMWP_COL!$B$2:$B$103,MATCH($I7,BMWP_COL!$A$2:$A$103,0)),"No aplica") -> 8 | Q7: =+SUM(K7:K628) -> 5270
A8: 45625 | B8: Medio | C8: La Lisa | D8: 11°13'46,7" N | E8: 74°01'23,1" W | F8: Arena | G8: 2 | H8: Hemiptera | I8: Naucoridae | J8: Limnocoris | K8: 1 | L8: =(K8/$Q$7)*100 -> 0.018975332 | M8: Pr | N8: =IFERROR(INDEX(BMWP_COL!$B$2:$B$103,MATCH($I8,BMWP_COL!$A$2:$A$103,0)),"No aplica") -> 7
A9: 45625 | B9: Medio | C9: La Lisa | D9: 11°13'46,7" N | E9: 74°01'23,1" W | F9: Arena | G9: 2 | H9: Diptera | I9: Chironomidae | J9: Chironominae | K9: 6 | L9: =(K9/$Q$7)*100 -> 0.11385199 | M9: CG | N9: =IFERROR(INDEX(BMWP_COL!$B$2:$B$103,MATCH($I9,BMWP_COL!$A$2:$A$103,0)),"No aplica") -> 2
A10: 45625 | B10: Medio | C10: La Lisa | D10: 11°13'46,7" N | E10: 74°01'23,1" W | F10: Arena | G10: 2 | H10: Hemiptera | I10: Veliidae | J10: Microvelia | K10: 34 | L10: =(K10/$Q$7)*100 -> 0.64516129 | M10: Pr | N10: =IFERROR(INDEX(BMWP_COL!$B$2:$B$103,MATCH($I10,BMWP_COL!$A$2:$A$103,0)),"No aplica") -> 8
A11: 45625 | B11: Medio | C11: La Lisa | D11: 11°13'46,7" N | E11: 74°01'23,1" W | F11: Arena | G11: 2 | H11: Hemiptera | I11: Veliidae | J11: Rhagovelia | K11: 1 | L11: =(K11/$Q$7)*100 -> 0.018975332 | M11: Pr | N11: =IFERROR(INDEX(BMWP_COL!$B$2:$B$103,MATCH($I11,BMWP_COL!$A$2:$A$103,0)),"No aplica") -> 8
A12: 45625 | B12: Medio | C12: La Lisa | D12: 11°13'46,7" N | E12: 74°01'23,1" W | F12: Arena | G12: 2 | H12: Ephemeroptera | I12: Baetidae | J12: Baetodes | K12: 6 | L12: =(K12/$Q$7)*100 -> 0.11385199 | M12: Ras | N12: =IFERROR(INDEX(BMWP_COL!$B$2:$B$103,MATCH($I12,BMWP_COL!$A$2:$A$103,0)),"No aplica") -> 7
A13: 45625 | B13: Medio | C13: La Lisa | D13: 11°13'46,7" N | E13: 74°01'23,1" W | F13: Arena | G13: 2 | H13: Ephemeroptera | I13: Baetidae | J13: Americabaetis | K13: 11 | L13: =(K13/$Q$7)*100 -> 0.20872865 | M13: CG | N13: =IFERROR(INDEX(BMWP_COL!$B$2:$B$103,MATCH($I13,BMWP_COL!$A$2:$A$103,0)),"No aplica") -> 7
A14: 45625 | B14: Medio | C14: La Lisa | D14: 11°13'46,7" N | E14: 74°01'23,1" W | F14: Arena | G14: 3 | H14: Hemiptera | I14: Naucoridae | J14: Limnocoris | K14: 3 | L14: =(K14/$Q$7)*100 -> 0.056925996 | M14: Pr | N14: =IFERROR(INDEX(BMWP_COL!$B$2:$B$103,MATCH($I14,BMWP_COL!$A$2:$A$103,0)),"No aplica") -> 7
A15: 45625 | B15: Medio | C15: La Lisa | D15: 11°13'46,7" N | E15: 74°01'23,1" W | F15: Arena | G15: 3 | H15: Diptera | I15: Chironomidae | J15: Chironominae | K15: 5 | L15: =(K15/$Q$7)*100 -> 0.09487666 | M15: CG | N15: =IFERROR(INDEX(BMWP_COL!$B$2:$B$103,MATCH($I15,BMWP_COL!$A$2:$A$103,0)),"No aplica") -> 2
A16: 45625 | B16: Medio | C16: La Lisa | D16: 11°13'46,7" N | E16: 74°01'23,1" W | F16: Arena | G16: 3 | H16: Diptera | I16: Chironomidae | J16: Tanypodinae | K16: 1 | L16: =(K16/$Q$7)*100 -> 0.018975332 | M16: Pr | N16: =IFERROR(INDEX(BMWP_COL!$B$2:$B$103,MATCH($I16,BMWP_COL!$A$2:$A$103,0)),"No aplica") -> 2
A17: 45625 | B17: Medio | C17: La Lisa | D17: 11°13'46,7" N | E17: 74°01'23,1" W | F17: Arena | G17: 3 | H17: Hemiptera | I17: Veliidae | J17: Rhagovelia | K17: 1 | L17: =(K17/$Q$7)*100 -> 0.018975332 | M17: Pr | N17: =IFERROR(INDEX(BMWP_COL!$B$2:$B$103,MATCH($I17,BMWP_COL!$A$2:$A$103,0)),"No aplica") -> 8
A18: 45625 | B18: Medio | C18: La Lisa | D18: 11°13'46,7" N | E18: 74°01'23,1" W | F18: Arena | G18: 3 | H18: Odonata | I18: Gomphidae | J18: Progomphus | K18: 1 | L18: =(K18/$Q$7)*100 -> 0.018975332 | M18: Pr | N18: =IFERROR(INDEX(BMWP_COL!$B$2:$B$103,MATCH($I18,BMWP_COL!$A$2:$A$103,0)),"No aplica") -> 10
A19: 45625 | B19: Medio | C19: La Lisa | D19: 11°13'46,7" N | E19: 74°01'23,1" W | F19: Arena | G19: 3 | H19: Diptera | I19: Limoniidae | J19: Limonia | K19: 1 | L19: =(K19/$Q$7)*100 -> 0.018975332 | M19: Pr | N19: =IFERROR(INDEX(BMWP_COL!$B$2:$B$103,MATCH($I19,BMWP_COL!$A$2:$A$103,0)),"No aplica") -> 4
... A196: 45625 | B196: Alto | C196: Bocatoma | D196: 11°12'37,1" N | E196: 74°02'10,30" W | F196: Raíz | G196: 2 | H196: Coleoptera | I196: Elmidae | J196: Phanocerus | K196: 3 | L196: =(K196/$Q$7)*100 -> 0.056925996 | M196: CG | N196: =IFERROR(INDEX(BMWP_COL!$B$2:$B$103,MATCH($I196,BMWP_COL!$A$2:$A$103,0)),"No aplica") -> 6
A197: 45625 | B197: Alto | C197: Bocatoma | D197: 11°12'37,1" N | E197: 74°02'10,30" W | F197: Raíz | G197: 2* | H197: Trichoptera | I197: Calamoceratidae | J197: Phylloicus | K197: 8 | L197: =(K197/$Q$7)*100 -> 0.15180266 | M197: Sh-Dt | N197: =IFERROR(INDEX(BMWP_COL!$B$2:$B$103,MATCH($I197,BMWP_COL!$A$2:$A$103,0)),"No aplica") -> 10
A198: 45625 | B198: Alto | C198: Bocatoma | D198: 11°12'37,1" N | E198: 74°02'10,30" W | F198: Raíz | G198: 2* | H198: Hemiptera | I198: Naucoridae | J198: Limnocoris | K198: 31 | L198: =(K198/$Q$7)*100 -> 0.58823529 | M198: Pr | N198: =IFERROR(INDEX(BMWP_COL!$B$2:$B$103,MATCH($I198,BMWP_COL!$A$2:$A$103,0)),"No aplica") -> 7
A199: 45625 | B199: Alto | C199: Bocatoma | D199: 11°12'37,1" N | E199: 74°02'10,30" W | F199: Raíz | G199: 2* | H199: Trichoptera | I199: Leptoceridae | J199: Atanatolica | K199: 76 | L199: =(K199/$Q$7)*100 -> 1.4421252 | M199: CG | N199: =IFERROR(INDEX(BMWP_COL!$B$2:$B$103,MATCH($I199,BMWP_COL!$A$2:$A$103,0)),"No aplica") -> 8
A200: 45625 | B200: Alto | C200: Bocatoma | D200: 11°12'37,1" N | E200: 74°02'10,30" W | F200: Raíz | G200: 2* | H200: Diptera | I200: Chironomidae | J200: Chironominae | K200: 56 | L200: =(K200/$Q$7)*100 -> 1.0626186 | M200: CG | N200: =IFERROR(INDEX(BMWP_COL!$B$2:$B$103,MATCH($I200,BMWP_COL!$A$2:$A$103,0)),"No aplica") -> 2
A201: 45625 | B201: Alto | C201: Bocatoma | D201: 11°12'37,1" N | E201: 74°02'10,30" W | F201: Raíz | G201: 2* | H201: Plecoptera | I201: Perlidae | J201: Anacroneuria | K201: 8 | L201: =(K201/$Q$7)*100 -> 0.15180266 | M201: Pr | N201: =IFERROR(INDEX(BMWP_COL!$B$2:$B$103,MATCH($I201,BMWP_COL!$A$2:$A$103,0)),"No aplica") -> 10
A202: 45625 | B202: Alto | C202: Bocatoma | D202: 11°12'37,1" N | E202: 74°02'10,30" W | F202: Raíz | G202: 2* | H202: Coleoptera | I202: Ptilodactylidae | J202: Anchytarsus | K202: 5 | L202: =(K202/$Q$7)*100 -> 0.09487666 | M202: Sh-Dt | N202: =IFERROR(INDEX(BMWP_COL!$B$2:$B$103,MATCH($I202,BMWP_COL!$A$2:$A$103,0)),"No aplica") -> 10
A203: 45625 | B203: Alto | C203: Bocatoma | D203: 11°12'37,1" N | E203: 74°02'10,30" W | F203: Raíz | G203: 2* | H203: Diptera | I203: Chironomidae | J203: Tanypodinae | K203: 18 | L203: =(K203/$Q$7)*100 -> 0.34155598 | M203: Pr | N203: =IFERROR(INDEX(BMWP_COL!$B$2:$B$103,MATCH($I203,BMWP_COL!$A$2:$A$103,0)),"No aplica") -> 2
A204: 45625 | B204: Alto | C204: Bocatoma | D204: 11°12'37,1" N | E204: 74°02'10,30" W | F204: Raíz | G204: 2* | H204: Coleoptera | I204: Elmidae | J204: Heterelmis | K204: 39 | L204: =(K204/$Q$7)*100 -> 0.74003795 | M204: CG | N204: =IFERROR(INDEX(BMWP_COL!$B$2:$B$103,MATCH($I204,BMWP_COL!$A$2:$A$103,0)),"No aplica") -> 6
A205: 45625 | B205: Alto | C205: Bocatoma | D205: 11°12'37,1" N | E205: 74°02'10,30" W | F205: Raíz | G205: 2* | H205: Ephemeroptera | I205: Baetidae | J205: Americabaetis | K205: 9 | L205: =(K205/$Q$7)*100 -> 0.17077799 | M205: CG | N205: =IFERROR(INDEX(BMWP_COL!$B$2:$B$103,MATCH($I205,BMWP_COL!$A$2:$A$103,0)),"No aplica") -> 7
A206: 45625 | B206: Alto | C206: Bocatoma | D206: 11°12'37,1" N | E206: 74°02'10,30" W | F206: Raíz | G206: 2* | H206: Ephemeroptera | I206: Leptohyphidae | J206: Leptohyphes | K206: 6 | L206: =(K206/$Q$7)*100 -> 0.11385199 | M206: CG | N206: =IFERROR(INDEX(BMWP_COL!$B$2:$B$103,MATCH($I206,BMWP_COL!$A$2:$A$103,0)),"No aplica") -> 7
A207: 45625 | B207: Alto | C207: Bocatoma | D207: 11°12'37,1" N | E207: 74°02'10,30" W | F207: Raíz | G207: 2* | H207: Ephemeroptera | I207: Leptohyphidae | J207: Tricorythodes | K207: 10 | L207: =(K207/$Q$7)*100 -> 0.18975332 | M207: CG | N207: =IFERROR(INDEX(BMWP_COL!$B$2:$B$103,MATCH($I207,BMWP_COL!$A$2:$A$103,0)),"No aplica") -> 7
A208: 45625 | B208: Alto | C208: Bocatoma | D208: 11°12'37,1" N | E208: 74°02'10,30" W | F208: Raíz | G208: 2* | H208: Odonata | I208: Calopterygidae | J208: Hetaerina | K208: 1 | L208: =(K208/$Q$7)*100 -> 0.018975332 | M208: Pr | N208: =IFERROR(INDEX(BMWP_COL!$B$2:$B$103,MATCH($I208,BMWP_COL!$A$2:$A$103,0)),"No aplica") -> 7
... A218: 45625 | B218: Alto | C218: Bocatoma | D218: 11°12'37,1" N | E218: 74°02'10,30" W | F218: Raíz | G218: 2* | H218: Diptera | I218: Dixidae | J218: Dixella | K218: 1 | L218: =(K218/$Q$7)*100 -> 0.018975332 | M218: CG | N218: =IFERROR(INDEX(BMWP_COL!$B$2:$B$103,MATCH($I218,BMWP_COL!$A$2:$A$103,0)),"No aplica") -> 7
A219: 45625 | B219: Alto | C219: Bocatoma | D219: 11°12'37,1" N | E219: 74°02'10,30" W | F219: Raíz | G219: 1 | H219: Ephemeroptera | I219: Baetidae | J219: Americabaetis | K219: =4+7 -> 11 | L219: =(K219/$Q$7)*100 -> 0.20872865 | M219: CG | N219: =IFERROR(INDEX(BMWP_COL!$B$2:$B$103,MATCH($I219,BMWP_COL!$A$2:$A$103,0)),"No aplica") -> 7
A220: 45625 | B220: Alto | C220: Bocatoma | D220: 11°12'37,1" N | E220: 74°02'10,30" W | F220: Raíz | G220: 1 | H220: Ephemeroptera | I220: Leptohyphidae | J220: Leptohyphes | K220: 1 | L220: =(K220/$Q$7)*100 -> 0.018975332 | M220: CG | N220: =IFERROR(INDEX(BMWP_COL!$B$2:$B$103,MATCH($I220,BMWP_COL!$A$2:$A$103,0)),"No aplica") -> 7
A221: 45625 | B221: Alto | C221: Bocatoma | D221: 11°12'37,1" N | E221: 74°02'10,30" W | F221: Raíz | G221: 1 | H221: Hemiptera | I221: Naucoridae | J221: Limnocoris | K221: 1 | L221: =(K221/$Q$7)*100 -> 0.018975332 | M221: Pr | N221: =IFERROR(INDEX(BMWP_COL!$B$2:$B$103,MATCH($I221,BMWP_COL!$A$2:$A$103,0)),"No aplica") -> 7
A222: 45625 | B222: Alto | C222: Bocatoma | D222: 11°12'37,1" N | E222: 74°02'10,30" W | F222: Raíz | G222: 1 | H222: Trichoptera | I222: Leptoceridae | J222: Atanatolica | K222: 1 | L222: =(K222/$Q$7)*100 -> 0.018975332 | M222: CG | N222: =IFERROR(INDEX(BMWP_COL!$B$2:$B$103,MATCH($I222,BMWP_COL!$A$2:$A$103,0)),"No aplica") -> 8
A223: 45625 | B223: Alto | C223: Bocatoma | D223: 11°12'37,1" N | E223: 74°02'10,30" W | F223: Raíz | G223: 1 | H223: Trichoptera | I223: Hydropsychidae | J223: Leptonema | K223: 2 | L223: =(K223/$Q$7)*100 -> 0.037950664 | M223: Sh-Dt | N223: =IFERROR(INDEX(BMWP_COL!$B$2:$B$103,MATCH($I223,BMWP_COL!$A$2:$A$103,0)),"No aplica") -> 7
A224: 45625 | B224: Alto | C224: Bocatoma | D224: 11°12'37,1" N | E224: 74°02'10,30" W | F224: Raíz | G224: 1 | H224: Coleoptera | I224: Elmidae | J224: Heterelmis | K224: 1 | L224: =(K224/$Q$7)*100 -> 0.018975332 | M224: CG | N224: =IFERROR(INDEX(BMWP_COL!$B$2:$B$103,MATCH($I224,BMWP_COL!$A$2:$A$103,0)),"No aplica") -> 6
A225: 45625 | B225: Alto | C225: Bocatoma | D225: 11°12'37,1" N | E225: 74°02'10,30" W | F225: Raíz | G225: 1 | H225: Ephemeroptera | I225: Baetidae | J225: Baetodes | K225: 21 | L225: =(K225/$Q$7)*100 -> 0.39848197 | M225: Ras | N225: =IFERROR(INDEX(BMWP_COL!$B$2:$B$103,MATCH($I225,BMWP_COL!$A$2:$A$103,0)),"No aplica") -> 7
A226: 45625 | B226: Alto | C226: Bocatoma | D226: 11°12'37,1" N | E226: 74°02'10,30" W | F226: Raíz | G226: 1 | H226: Diptera | I226: Simuliidae | J226: Simulium | K226: 1 | L226: =(K226/$Q$7)*100 -> 0.018975332 | M226: Ft | N226: =IFERROR(INDEX(BMWP_COL!$B$2:$B$103,MATCH($I226,BMWP_COL!$A$2:$A$103,0)),"No aplica") -> 8
A227: 45625 | B227: Alto | C227: Bocatoma | D227: 11°12'37,1" N | E227: 74°02'10,30" W | F227: Raíz | G227: 1 | H227: Coleoptera | I227: Psephenidae | J227: Psephenus | K227: 1 | L227: =(K227/$Q$7)*100 -> 0.018975332 | M227: Ras | N227: =IFERROR(INDEX(BMWP_COL!$B$2:$B$103,MATCH($I227,BMWP_COL!$A$2:$A$103,0)),"No aplica") -> 10
...

Sheet Peces
A2: Fecha | B2: Sitio | C2: Tramo | D2: Muestra | E2: Orden | F2: Familia | G2: Género | H2: Especie | I2: Abundancia | J2: FORMA ALETA CAUDAL | K2: Hábito Migratorio | L2: Microhabitat | M2: Posición bucal | N2: Tolerancia | O2: Gremios tróficos | P2: Comentario gremio trófico
A3: 45625 | B3: La Lisa | C3: Medio | D3: Diurna | E3: Characiformes | F3: Stevardiidae | G3: Hemibrycon | H3: Hemibrycon cf sierraensis | I3: 30 | J3: Emarginada | K3: Estacionario | L3: Pelágico | M3: Terminal | N3: Sensible | O3: Omnívoro | P3: Ibarra-Trujillo y García-Alzate (2017) en otra literatura: Insectivoro/ generalista
A4: 45625 | B4: La Lisa | C4: Medio | D4: Diurna | E4: Gobiiformes | F4: Gobiidae | G4: Sicydium | H4: Sicydium cf antillarum | I4: 70 | J4: Redondeada | K4: Catádromo | L4: Bentónico | M4: Inferior | N4: Sensible | O4: Herbívoro | P4: Silva (1990) Microherbívoro/ algas filamentosas y bacterias
A5: 45625 | B5: La Lisa | C5: Medio | D5: Diurna | E5: Mugiliformes | F5: Mugilidae | G5: Dajaus | H5: Dajaus monticola | I5: 20 | J5: Emarginada | K5: Catádromo | L5: Pelágico | M5: Terminal | N5: Sensible | O5: Omnívoro | P5: Matamoros et al (2021) en otra literatura: insectivoro/ carnívoro / generalista
A6: 45625 | B6: Bocatoma | C6: Alto | D6: Diurna | E6: Gobiiformes | F6: Gobiidae | G6: Sicydium | H6: Sicydium cf antillarum | I6: 30 | J6: Redondeada | K6: Catádromo | L6: Bentónico | M6: Inferior | N6: Sensible | O6: Herbívoro | P6: Silva (1990) Microherbívoro/ algas filamentosas y bacterias
A7: 45638 | B7: Los Naranjos | C7: Bajo | D7: Diurna | E7: Characiformes | F7: Stevardiidae | G7: Hemibrycon | H7: Hemibrycon cf sierraensis | I7: 9 | J7: Emarginada | K7: Estacionario | L7: Pelágico | M7: Terminal | N7: Sensible | O7: Omnívoro | P7: Ibarra-Trujillo y García-Alzate (2017) en otra literatura: Insectivoro/ generalista
A8: 45638 | B8: Los Naranjos | C8: Bajo | D8: Diurna | E8: Gobiiformes | F8: Gobiidae | G8: Sicydium | H8: Sicydium cf antillarum | I8: 72 | J8: Redondeada | K8: Catádromo | L8: Bentónico | M8: Inferior | N8: Sensible | O8: Herbívoro | P8: Silva (1990) Microherbívoro/ algas filamentosas y bacterias
A9: 45638 | B9: Los Naranjos | C9: Bajo | D9: Diurna | E9: Cichliformes | F9: Cichlidae | G9: Andinoacara | H9: Andinoacara latifrons | I9: 6 | J9: Redondeada | K9: Estacionario | L9: Pelágico | M9: Protractil | N9: Tolerante | O9: Omnívoro | P9: Blanco Cervantes (2020) En otra literatura: Especialista / Piscívoras/ depredador
A10: 45638 | B10: Los Naranjos | C10: Bajo | D10: Diurna | E10: Cyprinodontiformes | F10: Poeciliidae | G10: Poecilia | H10: Poecilia gillii | I10: 15 | J10: Redondeada | K10: Estacionario | L10: Pelágico | M10: Superior | N10: Tolerante | O10: Herbívoro | P10: Jimenez Prado et al (2020) Detritívoro
A11: 45638 | B11: Los Naranjos | C11: Bajo | D11: Diurna | E11: Mugiliformes | F11: Mugilidae | G11: Dajaus | H11: Dajaus monticola | I11: 30 | J11: Emarginada | K11: Catádromo | L11: Pelágico | M11: Terminal | N11: Sensible | O11: Omnívoro | P11: Matamoros et al (2021) en otra literatura: insectivoro/ carnívoro / generalista
A12: 45638 | B12: Los Naranjos | C12: Bajo | D12: Diurna | E12: Gobiiformes | F12: Gobiidae | G12: Sicydium | H12: Sicydium cf antillarum | I12: 60 | J12: Redondeada | K12: Catádromo | L12: Bentónico | M12: Inferior | N12: Sensible | O12: Herbívoro | P12: Silva (1990) Microherbívoro/ algas filamentosas y bacterias
A13: 45638 | B13: Los Naranjos | C13: Bajo | D13: Diurna | E13: Gobiiformes | F13: Eleotridae | G13: Eleotris | H13: Eleotris pisonis | I13: 6 | J13: Redondeada | K13: Catádromo | L13: Bentónico | M13: Inferior | N13: Tolerante | O13: Carnívoro | P13: Silva y Tavares (2023)
A14: 45638 | B14: Los Naranjos | C14: Bajo | D14: Diurna | E14: Gobiiformes | F14: Eleotridae | G14: Gobiomorus | H14: Gobiomorus maculatus | I14: 3 | J14: Redondeada | K14: Catádromo | L14: Pelágico | M14: Terminal | N14: Tolerante | O14: Omnívoro | P14: Canales-Gomez et al (2024) se alimentan de pequeños crustáceos y plantas / Carnívoro
A15: 45638 | B15: Los Naranjos | C15: Bajo | D15: Diurna | E15: Mugiliformes | F15: Mugilidae | G15: Dajaus | H15: Dajaus monticola | I15: 20 | J15: Emarginada | K15: Catádromo | L15: Pelágico | M15: Terminal | N15: Sensible | O15: Omnívoro | P15: Matamoros et al (2021) en otra literatura: insectivoro/ carnívoro / generalista
A16: 45779 | B16: Bocatoma | C16: Alto | D16: Diurna | E16: N/A | F16: N/A | G16: N/A | H16: N/A | I16: N/A | J16: N/A | K16: N/A | L16: N/A | M16: N/A | N16: N/A | O16: N/A | P16: N/A
A17: 45780 | B17: La Lisa | C17: Medio | D17: Diurna | E17: Characiformes | F17: Stevardiidae | G17: Hemibrycon | H17: Hemibrycon cf sierraensis | I17: 56 | J17: Emarginada | K17: Estacionario | L17: Pelágico | M17: Terminal | N17: Sensible | O17: Omnívoro | P17: Ibarra-Trujillo y García-Alzate (2017) en otra literatura: Insectivoro/ generalista
A18: 45780 | B18: La Lisa | C18: Medio | D18: Diurna | E18: Gobiiformes | F18: Gobiidae | G18: Sicydium | H18: Sicydium cf antillarum | I18: 20 | J18: Redondeada | K18: Catádromo | L18: Bentónico | M18: Inferior | N18: Sensible | O18: Herbívoro | P18: Silva (1990) Microherbívoro/ algas filamentosas y bacterias
A19: 45780 | B19: La Lisa | C19: Medio | D19: Diurna | E19: Mugiliformes | F19: Mugilidae | G19: Dajaus | H19: Dajaus monticola | I19: 13 | J19: Emarginada | K19: Catádromo | L19: Pelágico | M19: Terminal | N19: Sensible | O19: Omnívoro | P19: Matamoros et al (2021) en otra literatura: insectivoro/ carnívoro / generalista
A20: 45780 | B20: Finca Atinkana | C20: Alto | D20: Diurna | E20: Siluriformes | F20: Trichomycteridae | G20: Trichomycterus | H20: Trichomycterus nigromaculatus | I20: 5 | J20: Redondeada | K20: Estacionario | L20: Bentónico | M20: Inferior | N20: Tolerante | O20: Omnívoro | P20: Ibarra-Trujillo y García Alzate (2023): omnívora con tendencia a insectivora generalista

Sheet Perifiton
A1: Nota: Para la construcción del índice sólo se tendran en cuenta los 11 géneros de diatomeas y los otros 4 géneros pertenecientes a otros grupos (cianobacterias y algas verdes: Phormidium, Oscillatoria, Closterium y Spirogyra) se toman como información complementaria descriptiva porque en la literatura se ha construido el índice principalmente con Diatomeas y existe una ocurrencia puntual de estos datos, lo que hace díficil su comparación con otros puntos de muestreo
A4: Fecha | B4: Tramo | C4: Sitio | D4: Lalitud | E4: Longitud | F4: Micro-Habitat | G4: Réplica | H4: Grupo | I4: Orden | J4: Familia / subfamilia | K4: Género | L4: Tolerancia | M4: Gremio ecológico (Rimet y Bouchez, 2012)
A5: 45625 | B5: Alto | C5: Bocatoma | D5: 11°12'37.1" N | E5: 74°02'10.30" W | F5: Hojarasca | G5: 2 | H5: Diatomea | I5: Achnanthales | J5: Achnanthaceae | K5: Achnanthes | L5: Sensible | M5: Bajo perfil
A6: 45625 | B6: Alto | C6: Bocatoma | D6: 11°12'37.1" N | E6: 74°02'10.30" W | F6: Hojarasca | G6: 2 | H6: Diatomea | I6: Bacillariales | J6: Bacillariaceae | K6: Nitzschia | L6: Tolerante | M6: Móvil
A7: 45625 | B7: Alto | C7: Bocatoma | D7: 11°12'37.1" N | E7: 74°02'10.30" W | F7: Arena | G7: 2 | H7: Diatomea | I7: Bacillariales | J7: Bacillariaceae | K7: Nitzschia | L7: Tolerante | M7: Móvil
A8: 45625 | B8: Medio | C8: La Lisa | D8: 11°13'46.7" N | E8: 74°01'23.1" W | F8: Arena | G8: 1 | H8: Diatomea | I8: Bacillariales | J8: Bacillariaceae | K8: Nitzschia | L8: Tolerante | M8: Móvil
A9: 45625 | B9: Medio | C9: La Lisa | D9: 11°13'46.7" N | E9: 74°01'23.1" W | F9: Hojarasca | G9: 3 | H9: Diatomea | I9: Bacillariales | J9: Bacillariaceae | K9: Nitzschia | L9: Tolerante | M9: Móvil
A10: 45625 | B10: Alto | C10: Bocatoma | D10: 11°12'37.1" N | E10: 74°02'10.30" W | F10: Hojarasca | G10: 2 | H10: Diatomea | I10: Cymbellales | J10: Cymbellaceae | K10: Cymbella | L10: Sensible | M10: Bajo perfil
A11: 45625 | B11: Alto | C11: Bocatoma | D11: 11°12'37.1" N | E11: 74°02'10.30" W | F11: Hojarasca | G11: 2 | H11: Diatomea | I11: Naviculales | J11: Naviculaceae | K11: Navicula | L11: Tolerante | M11: Móvil
A12: 45625 | B12: Alto | C12: Bocatoma | D12: 11°12'37.1" N | E12: 74°02'10.30" W | F12: Arena | G12: 2 | H12: Diatomea | I12: Naviculales | J12: Naviculaceae | K12: Navicula | L12: Tolerante | M12: Móvil
A13: 45625 | B13: Alto | C13: Bocatoma | D13: 11°12'37.1" N | E13: 74°02'10.30" W | F13: Arena | G13: 2 | H13: Diatomea | I13: Naviculales | J13: Naviculaceae | K13: Gyrosigma | L13: Tolerante | M13: Móvil
A14: 45625 | B14: Medio | C14: La Lisa | D14: 11°13'46.7" N | E14: 74°01'23.1" W | F14: Arena | G14: 1 | H14: Diatomea | I14: Naviculales | J14: Naviculaceae | K14: Gyrosigma | L14: Tolerante | M14: Móvil
A15: 45625 | B15: Medio | C15: La Lisa | D15: 11°13'46.7" N | E15: 74°01'23.1" W | F15: Arena | G15: 1 | H15: Diatomea | I15: Naviculales | J15: Naviculaceae | K15: Navicula | L15: Tolerante | M15: Móvil
A16: 45625 | B16: Medio | C16: La Lisa | D16: 11°13'46.7" N | E16: 74°01'23.1" W | F16: Hojarasca | G16: 3 | H16: Diatomea | I16: Naviculales | J16: Naviculaceae | K16: Navicula | L16: Tolerante | M16: Móvil
... A64: 45779 | B64: Alto | C64: Bocatoma | D64: 11°12'37.1" N | E64: 74°02'10.30" W | F64: Hojarasca | G64: 2 | H64: Diatomea | I64: Naviculales | J64: Naviculaceae | K64: Navicula | L64: Tolerante | M64: Móvil

Sheet Vegetacion
A2: Fecha: | B2: 45625
A3: Localidad: | B3: Rio Piedra
A5: Índice de Calidad de Riveras - IRQ | H5: Propuesta de reescalonamiento del IRQ a IIBveg
A7: Tabla 1.1. Datos del IRQ por sitio de muestreo | H7: 1. Agregación espacial de los sitios a tramos
A9: Atributo | B9: Segmento o tramo de franja ribereña | H9: Como el IRQ se tomaron en 4 sitios puntuales, el tramo bajo compuesto por Desembocadura + Zaino se propone hacer una ponderación aritmética simple tomando los valores de la tabla 1.2
B10: 1 (Desembocadura) | C10: 2 (Zaino) | D10: 3 (La Lisa) | E10: 4 (Bocatoma)
A11: 1A | B11: 8 | C11: 10 | D11: 5 | E11: 10
A12: 1B | B12: 6 | C12: 8 | D12: 6 | E12: 10
A13: 2A | B13: 8 | C13: 8 | D13: 4 | E13: 10 | H13: Tabla 1.2. Datos ajustados del IRQ tabla 1.1.
A14: 2B | B14: 4 | C14: 6 | D14: 5 | E14: 10
A15: 3A | B15: 8 | C15: 6 | D15: 6 | E15: 9 | H15: Atributo | I15: Tramos o segmentos del río
A16: 3B | B16: 5 | C16: 6 | D16: 7 | E16: 9 | I16: Bajo | J16: Medio | K16: Alto
A17: 4 | B17: 9 | C17: 8 | D17: 5 | E17: 9 | H17: 1A | I17: =+AVERAGE(B11:C11) -> 9 | J17: 5 | K17: 10
A18: 5 | B18: 6 | C18: 9 | D18: 4 | E18: 10 | H18: 1B | I18: =+AVERAGE(B12:C12) -> 7 | J18: 6 | K18: 10
A19: 6 | B19: 6 | C19: 10 | D19: 5 | E19: 9 | H19: 2A | I19: =+AVERAGE(B13:C13) -> 8 | J19: 4 | K19: 10
A20: 7 | B20: 7 | C20: 9 | D20: 4 | E20: 9 | H20: 2B | I20: =+AVERAGE(B14:C14) -> 5 | J20: 5 | K20: 10
A21: Total | B21: =SUM(B11:B20) -> 67 | C21: =SUM(C11:C20) -> 80 | D21: =SUM(D11:D20) -> 51 | E21: =SUM(E11:E20) -> 95 | H21: 3A | I21: =+AVERAGE(B15:C15) -> 7 | J21: 6 | K21: 9
A22: Valoración | B22: Regular | C22: Bueno | D22: Pobre | E22: Muy bueno | H22: 3B | I22: =+AVERAGE(B16:C16) -> 5.5 | J22: 7 | K22: 9
H23: 4 | I23: =+AVERAGE(B17:C17) -> 8.5 | J23: 5 | K23: 9
H24: 5 | I24: =+AVERAGE(B18:C18) -> 7.5 | J24: 4 | K24: 10
H25: 6 | I25: =+AVERAGE(B19:C19) -> 8 | J25: 5 | K25: 9
H26: 7 | I26: =+AVERAGE(B20:C20) -> 8 | J26: 4 | K26: 9
H27: Total | I27: =SUM(I17:I26) -> 73.5 | J27: =SUM(J17:J26) -> 51 | K27: =SUM(K17:K26) -> 95
H28: Valoración | I28: Regular | J28: Pobre | K28: Bueno
H30: 2. Reescala del IRQ a IIBveg
H32: Se realiza una reescala del IRQ (10 -120) a un IIBveg (0-1) equivalente y comparable con los componentes del IIB mediante la ecuación: IIBveg= (Valor observado IRQ - Valor mínimo posible del IRQ) / (Valor máximo posible del IRQ - Valor mínimo posible del IRQ)
H38: Valor mínimo IRQ | I38: 10
H39: Valor máximo IRQ | I39: 120
H41: Tramo | I41: IIBveg | J41: Interpretación IIB
H42: Bajo | I42: =(I27-$I$38)/($I$39-$I$38) -> 0.57727273 | J42: Moderada
H43: Medio | I43: =(J27-$I$38)/($I$39-$I$38) -> 0.37272727 | J43: Pobre
H44: Alto | I44: =(K27-$I$38)/($I$39-$I$38) -> 0.77272727 | J44: Bueno

Sheet Fisicoquímicos
C2: Localidad: | D2: Río Piedras | G2: Origen muestra: | H2: Agua superficial
A4: Tabla 1. Datos fisicoquímicos obtenidos del análisis de agua superficial
A6: Fecha de muestreo | B6: Tramo | C6: Sitio | D6: Estación | E6: Replica | F6: Temperatura | G6: Conductividad | H6: Oxígeno Disuelto | I6: pH | J6: Amonio | K6: Nitrito | L6: Nitrato | M6: Fosfato | N6: Clorofila | O6: Alcalinidad | P6: Color Real | Q6: Cloruros | R6: Dureza total | S6: Calcio | T6: Magnesio | U6: Hierro total | V6: Manganeso | W6: Sulfatos | X6: Silice | Y6: Turbiedad | Z6: Coliformes totales | AA6: E. coli
F7: oC | G7: µsm/cm | H7: mg/L | I7: unidades | J7: mg NH3/ L | K7: mg NO2/ L | L7: mg NO3/ L | M7: mg PO4/ L | O7: mg/l CaCO3 | P7: upc | Q7: mg Cl/l | R7: mg CaCO3/l | S7: mg Ca/L | T7: mg Mg/l | U7: mg Fe/l | V7: mg Mn/l | W7: mg SO4/l | X7: mg/l Si | Y7: UNT | Z7: UFC/ 100 ml | AA7: UFC/ 100 ml
A8: 45625 | B8: Medio | C8: La Lisa | D8: P1 Qb La Lisa | E8: 1 | J8: <0,001 | K8: 0.034 | L8: 0.055 | M8: 0.103 | O8: 68.5 | P8: 7 | Q8: 13.64 | R8: 88 | S8: 14.82 | T8: 12.39 | U8: 0.074 | V8: <0,01 | W8: 14.91 | X8: 14.41 | Y8: 3.33 | Z8: 1300 | AA8: 190
A9: 45625 | B9: Medio | C9: La Lisa | D9: P2 Río Piebras | E9: 2 | J9: <0,001 | K9: 0.033 | L9: 0.072 | M9: 0.043 | O9: 59.5 | P9: 6 | Q9: 14.89 | R9: 49.5 | S9: 9.42 | T9: 6.34 | U9: 0.038 | V9: <0,01 | W9: 12.92 | X9: 13.83 | Y9: 1.57 | Z9: 1800 | AA9: 170
A10: 45625 | B10: Alto | C10: Bocatoma | D10: P3 Bocatoma | E10: 1 | J10: <0,001 | K10: 0.035 | L10: 0.062 | M10: 0.031 | O10: 55 | P10: 7 | Q10: 12.4 | R10: 49.1 | S10: 7.01 | T10: 5.77 | U10: 0.028 | V10: <0,01 | W10: 10.2 | X10: 11.5 | Y10: 3.29 | Z10: 1500 | AA10: 150
A11: 45625 | B11: Bajo | C11: Los Naranjos | D11: Parte baja Río | E11: 1 | J11: <0,001 | K11: 0.037 | L11: 0.069 | M11: 0.129 | O11: 71 | P11: 8 | Q11: 21.09 | R11: 55 | S11: 8.62 | T11: 8.14 | U11: 0.187 | V11: <0,01 | W11: 11.63 | X11: 15.08 | Y11: 6.88 | Z11: 2100 | AA11: 310
A12: 45625 | B12: Bajo | C12: Desembocadura | D12: Parte baja puente | E12: 2 | J12: <0,001 | K12: 0.04 | L12: 0.072 | M12: 0.124 | O12: 71.3 | P12: 7 | Q12: 23.33 | R12: 57.7 | S12: 9.02 | T12: 8.57 | U12: 0.172 | V12: <0,01 | W12: 11.46 | X12: 14.45 | Y12: 8.54 | Z12: 2400 | AA12: 370
A13: 45625 | B13: Bajo | C13: Los Naranjos | D13: Punto bajo río Piedras | E13: 3 | J13: <0,001 | K13: 0.035 | L13: 0.084 | M13: 0.111 | O13: 77.5 | P13: 6 | Q13: 24.81 | R13: 52.5 | S13: 9.04 | T13: 7.23 | U13: 0.203 | V13: <0,01 | W13: 11.63 | X13: 14.93 | Y13: 16.3 | Z13: 2700 | AA13: 410
A14: 45779 | B14: Alto | C14: Bocatoma | D14: Bocatoma | E14: 1 | G14: 89.5 | I14: 7.2 | J14: 0.0002 | K14: 0.0383 | L14: 0.0716 | M14: 0.0214 | O14: 55 | P14: 6 | Q14: 39.7 | R14: 46.75 | S14: 9.62 | T14: 5.53 | U14: 0.0946 | V14: <0,01 | W14: 2.64 | X14: 12.19 | Y14: 5.45 | Z14: 1450 | AA14: 250
A15: 45780 | B15: Alto | C15: Atinkana | D15: Quebrada finca Atinkana | E15: 1 | F15: 23.97 | G15: 63.2 | H15: 13.37 | I15: 6.77 | J15: 0.0001 | K15: 0.0302 | L15: 0.0716 | M15: <0,004 | O15: 33 | P15: 5 | Q15: 35.98 | R15: 30.25 | S15: 6.41 | T15: 3.46 | U15: 0.0432 | V15: <0,01 | W15: 2.18 | X15: 10.77 | Y15: 1.38 | Z15: 990 | AA15: 140
A18: Tabla 2. Datos fisicoquímicos empleados para el análisis
A20: Tramo /sitio | B20: Nitrito | C20: Nitrato | D20: Fosfato | E20: Alcalinidad | F20: Cloruros | G20: Dureza total | H20: Calcio | I20: Magnesio | J20: Hierro total | K20: Sulfatos | L20: Silice | M20: Turbiedad | N20: Coliformes totales | O20: E. coli
B21: mg NO2/ L | C21: mg NO3/ L | D21: mg PO4/ L | E21: mg/l CaCO3 | F21: mg Cl/l | G21: mg CaCO3/l | H21: mg Ca/L | I21: mg Mg/l | J21: mg Fe/l | K21: mg SO4/l | L21: mg/l Si | M21: UNT | N21: UFC/ 100 ml | O21: UFC/ 100 ml
A22: Bajo | B22: =+AVERAGE($K$11:$K$13) -> 0.037333333 | C22: =+AVERAGE($L$11:$L$13) -> 0.075 | D22: =+AVERAGE($M$11:$M$13) -> 0.12133333 | E22: =+AVERAGE($O$11:$O$13) -> 73.266667 | F22: =+AVERAGE($Q$11:$Q$13) -> 23.076667 | G22: =+AVERAGE($R$11:$R$13) -> 55.066667 | H22: =+AVERAGE($S$11:$S$13) -> 8.8933333 | I22: =+AVERAGE($T$11:$T$13) -> 7.98 | J22: =+AVERAGE($U$11:$U$13) -> 0.18733333 | K22: =+AVERAGE($W$11:$W$13) -> 11.573333 | L22: =+AVERAGE($X$11:$X$13) -> 14.82 | M22: =+AVERAGE($Y$11:$Y$13) -> 10.573333 | N22: =+AVERAGE($Z$11:$Z$13) -> 2400 | O22: =+AVERAGE($AA$11:$AA$13) -> 363.33333
A23: Medio | B23: =+AVERAGE($K$8:$K$9) -> 0.0335 | C23: =+AVERAGE($L$8:$L$9) -> 0.0635 | D23: =+AVERAGE($M$8:$M$9) -> 0.073 | E23: =+AVERAGE($O$8:$O$9) -> 64 | F23: =+AVERAGE($Q$8:$Q$9) -> 14.265 | G23: =+AVERAGE($R$8:$R$9) -> 68.75 | H23: =+AVERAGE($S$8:$S$9) -> 12.12 | I23: =+AVERAGE($T$8:$T$9) -> 9.365 | J23: =+AVERAGE($U$8:$U$9) -> 0.056 | K23: =+AVERAGE($W$8:$W$9) -> 13.915 | L23: =+AVERAGE($X$8:$X$9) -> 14.12 | M23: =+AVERAGE($Y$8:$Y$9) -> 2.45 | N23: =+AVERAGE($Z$8:$Z$9) -> 1550 | O23: =+AVERAGE($AA$8:$AA$9) -> 180
A24: Alto | B24: =+AVERAGE($K$14:$K$15,$K$10) -> 0.0345 | C24: =+AVERAGE($L$14:$L$15,$L$10) -> 0.0684 | D24: =+AVERAGE($M$14:$M$15,$M$10) -> 0.0262 | E24: =+AVERAGE($O$14:$O$15,$O$10) -> 47.666667 | F24: =+AVERAGE($Q$14:$Q$15,$Q$10) -> 29.36 | G24: =+AVERAGE($R$14:$R$15,$R$10) -> 42.033333 | H24: =+AVERAGE($S$14:$S$15,$S$10) -> 7.68 | I24: =+AVERAGE($T$14:$T$15,$T$10) -> 4.92 | J24: =+AVERAGE($U$14:$U$15,$U$10) -> 0.055266667 | K24: =+AVERAGE($W$14:$W$15,$W$10) -> 5.0066667 | L24: =+AVERAGE($X$14:$X$15,$X$10) -> 11.486667 | M24: =+AVERAGE($Y$14:$Y$15,$Y$10) -> 3.3733333 | N24: =+AVERAGE($Z$14:$Z$15,$Z$10) -> 1313.3333 | O24: =+AVERAGE($AA$14:$AA$15,$AA$10) -> 180
A26: Tramo /sitio | B26: Nitrito | C26: Nitrato | D26: Fosfato | E26: Alcalinidad | F26: Cloruros | G26: Dureza total | H26: Calcio | I26: Magnesio | J26: Hierro total | K26: Sulfatos | L26: Silice | M26: Turbiedad | N26: Coliformes totales | O26: E. coli
B27: mg NO2/ L | C27: mg NO3/ L | D27: mg PO4/ L | E27: mg/l CaCO3 | F27: mg Cl/l | G27: mg CaCO3/l | H27: mg Ca/L | I27: mg Mg/l | J27: mg Fe/l | K27: mg SO4/l | L27: mg/l Si | M27: UNT | N27: UFC/ 100 ml | O27: UFC/ 100 ml
A28: Desembocadura | B28: =$K$12 -> 0.04 | C28: =$L$12 -> 0.072 | D28: =$M$12 -> 0.124 | E28: =$O$12 -> 71.3 | F28: =$Q$12 -> 23.33 | G28: =$R$12 -> 57.7 | H28: =$S$12 -> 9.02 | I28: =$T$12 -> 8.57 | J28: =$U$12 -> 0.172 | K28: =$W$12 -> 11.46 | L28: =$X$12 -> 14.45 | M28: =$Y$12 -> 8.54 | N28: =$Z$12 -> 2400 | O28: =$AA$12 -> 370
A29: Los Naranjos | B29: =+AVERAGE($K$13,$K$11) -> 0.036 | C29: =+AVERAGE($L$13,$L$11) -> 0.0765 | D29: =+AVERAGE($M$13,$M$11) -> 0.12 | E29: =+AVERAGE($O$13,$O$11) -> 74.25 | F29: =+AVERAGE($Q$13,$Q$11) -> 22.95 | G29: =+AVERAGE($R$13,$R$11) -> 53.75 | H29: =+AVERAGE($S$13,$S$11) -> 8.83 | I29: =+AVERAGE($T$13,$T$11) -> 7.685 | J29: =+AVERAGE($U$13,$U$11) -> 0.195 | K29: =+AVERAGE($W$13,$W$11) -> 11.63 | L29: =+AVERAGE($X$13,$X$11) -> 15.005 | M29: =+AVERAGE($Y$13,$Y$11) -> 11.59 | N29: =+AVERAGE($Z$13,$Z$11) -> 2400 | O29: =+AVERAGE($AA$13,$AA$11) -> 360
A30: La Lisa | B30: =+AVERAGE($K$8:$K$9) -> 0.0335 | C30: =+AVERAGE($L$8:$L$9) -> 0.0635 | D30: =+AVERAGE($M$8:$M$9) -> 0.073 | E30: =+AVERAGE($O$8:$O$9) -> 64 | F30: =+AVERAGE($Q$8:$Q$9) -> 14.265 | G30: =+AVERAGE($R$8:$R$9) -> 68.75 | H30: =+AVERAGE($S$8:$S$9) -> 12.12 | I30: =+AVERAGE($T$8:$T$9) -> 9.365 | J30: =+AVERAGE($U$8:$U$9) -> 0.056 | K30: =+AVERAGE($W$8:$W$9) -> 13.915 | L30: =+AVERAGE($X$8:$X$9) -> 14.12 | M30: =+AVERAGE($Y$8:$Y$9) -> 2.45 | N30: =+AVERAGE($Z$8:$Z$9) -> 1550 | O30: =+AVERAGE($AA$8:$AA$9) -> 180
A31: Bocatoma | B31: =+AVERAGE($K$10,$K$14) -> 0.03665 | C31: =+AVERAGE($L$10,$L$14) -> 0.0668 | D31: =+AVERAGE($M$10,$M$14) -> 0.0262 | E31: =+AVERAGE($O$10,$O$14) -> 55 | F31: =+AVERAGE($Q$10,$Q$14) -> 26.05 | G31: =+AVERAGE($R$10,$R$14) -> 47.925 | H31: =+AVERAGE($S$10,$S$14) -> 8.315 | I31: =+AVERAGE($T$10,$T$14) -> 5.65 | J31: =+AVERAGE($U$10,$U$14) -> 0.0613 | K31: =+AVERAGE($W$10,$W$14) -> 6.42 | L31: =+AVERAGE($X$10,$X$14) -> 11.845 | M31: =+AVERAGE($Y$10,$Y$14) -> 4.37 | N31: =+AVERAGE($Z$10,$Z$14) -> 1475 | O31: =+AVERAGE($AA$10,$AA$14) -> 200
A32: Atinkana | B32: =+$J$15 -> 0.0001 | C32: =+$K$15 -> 0.0302 | D32: 0.004 | E32: =+$O$15 -> 33 | F32: =+$Q$15 -> 35.98 | G32: =+$R$15 -> 30.25 | H32: =+$S$15 -> 6.41 | I32: =+$T$15 -> 3.46 | J32: =+$U$15 -> 0.0432 | K32: =+$W$15 -> 2.18 | L32: =+$X$15 -> 10.77 | M32: =+$Y$15 -> 1.38 | N32: =+$Z$15 -> 990 | O32: =+$AA$15 -> 140

Sheet Chl-a
A1: Datos de clorofila
A3: Fecha | B3: Lugar | C3: Tramo | D3: Sustrato | E3: Replica | F3: Absorbancia | G3: Longitud de Onda | H3: Vol extracto (ml) | I3: Superficie (cm2) | L3: Tramo | M3: Sustrato | N3: Replica | O3: Chl-a | P3: Desviación estandar | Q3: Promedio Chl-a (sustrato) | R3: Promedio Chl-a (tramo)
A4: 45629 | B4: Rio Piedras | C4: Tramo Alto | D4: Roca | E4: 1 | F4: 430 | G4: 0.052 | H4: 10 | I4: 1 | L4: Tramo Alto Bocatoma | M4: Arena | N4: R1 | O4: 3.876 | P4: 1.8531576 | Q4: 1.1115 | R4: =+ AVERAGE(O4:O15) -> 1.463
A5: 45629 | B5: Rio Piedras | C5: Tramo Alto | D5: Roca | E5: 1 | F5: 665 | G5: 0.039 | H5: 10 | I5: 1 | L5: Tramo Alto Bocatoma | M5: Arena | N5: R2 | O5: 0.456
A6: 45629 | B6: Rio Piedras | C6: Tramo Alto | D6: Roca | E6: 1 | F6: 750 | G6: 0.034 | H6: 10 | I6: 1 | L6: Tramo Alto Bocatoma | M6: Arena | N6: R3 | O6: 0.114
A7: 45629 | B7: Rio Piedras | C7: Tramo Alto | D7: Roca | E7: 2 | F7: 430 | G7: 0.051 | H7: 10 | I7: 1 | L7: Tramo Alto Bocatoma | M7: Arena | N7: R4 | O7: 0
A8: 45629 | B8: Rio Piedras | C8: Tramo Alto | D8: Roca | E8: 2 | F8: 665 | G8: 0.039 | H8: 10 | I8: 1 | L8: Tramo Alto Bocatoma | M8: Hojarasca | N8: R1 | O8: 0.114 | P8: 0.40971331 | Q8: 0.4845
A9: 45629 | B9: Rio Piedras | C9: Tramo Alto | D9: Roca | E9: 2 | F9: 750 | G9: 0.035 | H9: 10 | I9: 1 | L9: Tramo Alto Bocatoma | M9: Hojarasca | N9: R2 | O9: 1.026
A10: 45629 | B10: Rio Piedras | C10: Tramo Alto | D10: Roca | E10: 3 | F10: 430 | G10: 0.067 | H10: 10 | I10: 1 | L10: Tramo Alto Bocatoma | M10: Hojarasca | N10: R3 | O10: 0.57
A11: 45629 | B11: Rio Piedras | C11: Tramo Alto | D11: Roca | E11: 3 | F11: 665 | G11: 0.047 | H11: 10 | I11: 1 | L11: Tramo Alto Bocatoma | M11: Hojarasca | N11: R4 | O11: 0.228
A12: 45629 | B12: Rio Piedras | C12: Tramo Alto | D12: Roca | E12: 3 | F12: 750 | G12: 0.034 | H12: 10 | I12: 1 | L12: Tramo Alto Bocatoma | M12: Roca | N12: R1 | O12: 2.394 | P12: 0.74754799 | Q12: 2.793
A13: 45629 | B13: Rio Piedras | C13: Tramo Alto | D13: Arena | E13: 1 | F13: 430 | G13: 0.137 | H13: 10 | I13: 1 | L13: Tramo Alto Bocatoma | M13: Roca | N13: R2 | O13: 3.42
A14: 45629 | B14: Rio Piedras | C14: Tramo Alto | D14: Arena | E14: 1 | F14: 665 | G14: 0.064 | H14: 10 | I14: 1 | L14: Tramo Alto Bocatoma | M14: Roca | N14: R3 | O14: 3.42
A15: 45629 | B15: Rio Piedras | C15: Tramo Alto | D15: Arena | E15: 1 | F15: 750 | G15: 0.037 | H15: 10 | I15: 1 | L15: Tramo Alto Bocatoma | M15: Roca | N15: R4 | O15: 1.938
A16: 45629 | B16: Rio Piedras | C16: Tramo Alto | D16: Arena | E16: 2 | F16: 430 | G16: 0.087 | H16: 10 | I16: 1 | L16: Tramo Medio La Lisa | M16: Roca | N16: R1 | O16: 0.912 | P16: 0.30161565 | Q16: 0.513 | R16: =+ AVERAGE(O16:O27) -> 0.513
A17: 45629 | B17: Rio Piedras | C17: Tramo Alto | D17: Arena | E17: 2 | F17: 665 | G17: 0.05 | H17: 10 | I17: 1 | L17: Tramo Medio La Lisa | M17: Roca | N17: R2 | O17: 0.228
A18: 45629 | B18: Rio Piedras | C18: Tramo Alto | D18: Arena | E18: 2 | F18: 750 | G18: 0.038 | H18: 10 | I18: 1 | L18: Tramo Medio La Lisa | M18: Roca | N18: R3 | O18: 0.57
A19: 45629 | B19: Rio Piedras | C19: Tramo Alto | D19: Arena | E19: 3 | F19: 430 | G19: 0.09 | H19: 10 | I19: 1 | L19: Tramo Medio La Lisa | M19: Roca | N19: R4 | O19: 0.342
A20: 45629 | B20: Rio Piedras | C20: Tramo Alto | D20: Arena | E20: 3 | F20: 665 | G20: 0.05 | H20: 10 | I20: 1 | L20: Tramo Medio La Lisa | M20: Hojarasca | N20: R1 | O20: 0.114 | P20: 0.70505106 | Q20: 0.5415
A21: 45629 | B21: Rio Piedras | C21: Tramo Alto | D21: Arena | E21: 3 | F21: 750 | G21: 0.036 | H21: 10 | I21: 1 | L21: Tramo Medio La Lisa | M21: Hojarasca | N21: R2 | O21: 1.596
A22: 45625 | B22: Rio Piedras | C22: Tramo Medio | D22: Roca | E22: 1 | F22: 430 | G22: 0.059 | H22: 10 | I22: 1 | L22: Tramo Medio La Lisa | M22: Hojarasca | N22: R3 | O22: 0.228
A23: 45625 | B23: Rio Piedras | C23: Tramo Medio | D23: Roca | E23: 1 | F23: 665 | G23: 0.043 | H23: 10 | I23: 1 | L23: Tramo Medio La Lisa | M23: Hojarasca | N23: R4 | O23: 0.228
A24: 45625 | B24: Rio Piedras | C24: Tramo Medio | D24: Roca | E24: 1 | F24: 750 | G24: 0.033 | H24: 10 | I24: 1 | L24: Tramo Medio La Lisa | M24: Arena | N24: R1 | O24: 0.114 | P24: 0.34041298 | Q24: 0.4845
A25: 45625 | B25: Rio Piedras | C25: Tramo Medio | D25: Roca | E25: 2 | F25: 430 | G25: 0.116 | H25: 10 | I25: 1 | L25: Tramo Medio La Lisa | M25: Arena | N25: R2 | O25: 0.912
A26: 45625 | B26: Rio Piedras | C26: Tramo Medio | D26: Roca | E26: 2 | F26: 665 | G26: 0.068 | H26: 10 | I26: 1 | L26: Tramo Medio La Lisa | M26: Arena | N26: R3 | O26: 0.342
A27: 45625 | B27: Rio Piedras | C27: Tramo Medio | D27: Roca | E27: 2 | F27: 750 | G27: 0.033 | H27: 10 | I27: 1 | L27: Tramo Medio La Lisa | M27: Arena | N27: R4 | O27: 0.57
A28: 45625 | B28: Rio Piedras | C28: Tramo Medio | D28: Roca | E28: 3 | F28: 430 | G28: 0.08 | H28: 10 | I28: 1 | L28: Tramo Alto San Isidro | M28: Arena | N28: R1 | O28: 0.114 | P28: 0.14717337 | Q28: 0.171 | R28: =+AVERAGE(O28:O39) -> 0.1615
A29: 45625 | B29: Rio Piedras | C29: Tramo Medio | D29: Roca | E29: 3 | F29: 665 | G29: 0.052 | H29: 10 | I29: 1 | L29: Tramo Alto San Isidro | M29: Arena | N29: R2 | O29: 0
A30: 45625 | B30: Rio Piedras | C30: Tramo Medio | D30: Roca | E30: 3 | F30: 750 | G30: 0.034 | H30: 10 | I30: 1 | L30: Tramo Alto San Isidro | M30: Arena | N30: R3 | O30: 0.342
A31: 45625 | B31: Rio Piedras | C31: Tramo Medio | D31: Hojarasca | E31: 1 | F31: 430 | G31: 0.049 | H31: 10 | I31: 1 | L31: Tramo Alto San Isidro | M31: Arena | N31: R4 | O31: 0.228
A32: 45625 | B32: Rio Piedras | C32: Tramo Medio | D32: Hojarasca | E32: 1 | F32: 665 | G32: 0.037 | H32: 10 | I32: 1 | L32: Tramo Alto San Isidro | M32: Roca | N32: R1 | O32: 0 | P32: 0.057 | Q32: 0.0855
A33: 45625 | B33: Rio Piedras | C33: Tramo Medio | D33: Hojarasca | E33: 1 | F33: 750 | G33: 0.033 | H33: 10 | I33: 1 | L33: Tramo Alto San Isidro | M33: Roca | N33: R2 | O33: 0.114
A34: 45625 | B34: Rio Piedras | C34: Tramo Medio | D34: Hojarasca | E34: 2 | F34: 430 | G34: 0.048 | H34: 10 | I34: 1 | L34: Tramo Alto San Isidro | M34: Roca | N34: R3 | O34: 0.114
A35: 45625 | B35: Rio Piedras | C35: Tramo Medio | D35: Hojarasca | E35: 2 | F35: 665 | G35: 0.038 | H35: 10 | I35: 1 | L35: Tramo Alto San Isidro | M35: Roca | N35: R4 | O35: 0.114
A36: 45625 | B36: Rio Piedras | C36: Tramo Medio | D36: Hojarasca | E36: 2 | F36: 750 | G36: 0.033 | H36: 10 | I36: 1 | L36: Tramo Alto San Isidro | M36: Hojarasca | N36: R1 | O36: 0.342 | P36: 0.09308061 | Q36: 0.228
A37: 45625 | B37: Rio Piedras | C37: Tramo Medio | D37: Hojarasca | E37: 3 | F37: 430 | G37: 0.037 | H37: 10 | I37: 1 | L37: Tramo Alto San Isidro | M37: Hojarasca | N37: R2 | O37: 0.228
A38: 45625 | B38: Rio Piedras | C38: Tramo Medio | D38: Hojarasca | E38: 3 | F38: 665 | G38: 0.033 | H38: 10 | I38: 1 | L38: Tramo Alto San Isidro | M38: Hojarasca | N38: R3 | O38: 0.114
A39: 45625 | B39: Rio Piedras | C39: Tramo Medio | D39: Hojarasca | E39: 3 | F39: 750 | G39: 0.032 | H39: 10 | I39: 1 | L39: Tramo Alto San Isidro | M39: Hojarasca | N39: R4 | O39: 0.228
A40: 45625 | B40: Rio Piedras | C40: Tramo Medio | D40: Arena | E40: 1 | F40: 430 | G40: 0.196 | H40: 10 | I40: 1 | L40: Tramo Alto Bocatoma | M40: Roca | N40: R1 | O40: 0.57 | P40: 0.56234865 | Q40: 0.836 | R40: =+AVERAGE(O40:O45) -> 1.425
A41: 45625 | B41: Rio Piedras | C41: Tramo Medio | D41: Arena | E41: 1 | F41: 665 | G41: 0.1 | H41: 10 | I41: 1 | L41: Tramo Alto Bocatoma | M41: Roca | N41: R2 | O41: 0.456
...

Sheet BMWP_COL
A1: Familia | B1: Puntaje BMWP/Col
A2: Anomalopsychidae | B2: 10
A3: Atriplectidae | B3: 10
A4: Blepharoceridae | B4: 10
A5: Calamoceratidae | B5: 10
A6: Ptilodactylidae | B6: 10
A7: Chordodidae | B7: 10
A8: Gomphidae | B8: 10
A9: Hydridae | B9: 10
A10: Lampyridae | B10: 10
A11: Lymnessiidae | B11: 10
A12: Odontoceridae | B12: 10
A13: Oligoneuriidae | B13: 10
... A103: Psephenidae | B103: 10

Sheet IIBMA
A1: IIB Macroinvertebrados Acuáticos
A3: Nota metodológica
A4: Referentes bibliográficos: Pinilla et al. (2008), Tabla 23. El índice de Hilsenhoff original se sustituye por BMWP/Col (Roldán, 2003) como proxy de tolerancia (ver nota en el prompt maestro del proyecto, "Inconsistencia abierta"). El cálculo de las métricas se realiza uniendo las dos campañas de muestreo (nov-dic 2024 y may 2025) para los tres tramos, aunque representa un sesgo por la falta de datos del tramo Bajo en la segunda campaña (may 2025) — decisión ya tomada por el equipo, se documenta aquí para que quede trazable junto al resto del componente. REVISIÓN METODOLÓGICA (esta versión): se revierte la estandarización min-max entre los 3 tramos (versión anterior de esta hoja) al puntaje absoluto de la Tabla 23 de Pinilla et al. (2008) — ver justificación completa en la hoja de notas del proyecto. Se usan las 10 métricas literales de la Tabla 23 (TT, T, D, %E, %EPT, %O, I, Tol, %CG, Ft) en vez de las 7 métricas simplificadas de la versión anterior (TT, EPTR, Ab, %EPT, %CG, %Ft, BMWP/Col), porque EPTR, Ab y BMWP/Col como métrica puntuable no tienen un corte absoluto literal en la Tabla 23. Se mantienen los datos crudos (abundancia por familia/género, ambas campañas) sin cambios. SUPUESTO marcado (Regla de rigor #4): I (taxones intolerantes) y Tol (% taxones tolerantes) se calculan usando BMWP/Col como proxy de tolerancia en vez del VT genuino de la Tabla 22 (no disponible a nivel de familia): se define "intolerante" como familia con BMWP/Col ≥ 7 y "tolerante" como familia con BMWP/Col ≤ 3 — un tercio alto y un tercio bajo del rango 1-10 de puntajes BMWP/Col, no un corte literal de la fuente. %O (Oligoquetos) se calcula sobre la familia Lumbriculidae (único oligoqueto presente en los datos).
A7: 1. Abundancia por familia y tramo (hoja "Macroinv.", ambas campañas)
A9: Orden | B9: Familia | C9: BMWP/Col | D9: Bajo | E9: Medio | F9: Alto
A10: Coleoptera | B10: Elmidae | C10: =IFERROR(INDEX(BMWP_COL!$B$2:$B$103,MATCH($B10,BMWP_COL!$A$2:$A$103,0)),"No aplica") -> 6 | D10: 28 | E10: 457 | F10: 372
A11: Coleoptera | B11: Hydrophilidae | C11: =IFERROR(INDEX(BMWP_COL!$B$2:$B$103,MATCH($B11,BMWP_COL!$A$2:$A$103,0)),"No aplica") -> 3 | D11: 0 | E11: 1 | F11: 13
A12: Coleoptera | B12: Psephenidae | C12: =IFERROR(INDEX(BMWP_COL!$B$2:$B$103,MATCH($B12,BMWP_COL!$A$2:$A$103,0)),"No aplica") -> 10 | D12: 0 | E12: 5 | F12: 28
A13: Coleoptera | B13: Ptilodactylidae | C13: =IFERROR(INDEX(BMWP_COL!$B$2:$B$103,MATCH($B13,BMWP_COL!$A$2:$A$103,0)),"No aplica") -> 10 | D13: 0 | E13: 11 | F13: 100
A14: Coleoptera | B14: Staphylinidae | C14: =IFERROR(INDEX(BMWP_COL!$B$2:$B$103,MATCH($B14,BMWP_COL!$A$2:$A$103,0)),"No aplica") -> 6 | D14: 1 | E14: 4 | F14: 3
A15: Decapoda | B15: Atyidae | C15: =IFERROR(INDEX(BMWP_COL!$B$2:$B$103,MATCH($B15,BMWP_COL!$A$2:$A$103,0)),"No aplica") -> 6 | D15: 268 | E15: 1 | F15: 6
A16: Decapoda | B16: Pseudothelphusidae | C16: =IFERROR(INDEX(BMWP_COL!$B$2:$B$103,MATCH($B16,BMWP_COL!$A$2:$A$103,0)),"No aplica") -> 8 | D16: 1 | E16: 0 | F16: 1
A17: Diptera | B17: Blepharoceridae | C17: =IFERROR(INDEX(BMWP_COL!$B$2:$B$103,MATCH($B17,BMWP_COL!$A$2:$A$103,0)),"No aplica") -> 10 | D17: 0 | E17: 0 | F17: 3
A18: Diptera | B18: Ceratopogonidae | C18: =IFERROR(INDEX(BMWP_COL!$B$2:$B$103,MATCH($B18,BMWP_COL!$A$2:$A$103,0)),"No aplica") -> 3 | D18: 1 | E18: 14 | F18: 7
A19: Diptera | B19: Chironomidae | C19: =IFERROR(INDEX(BMWP_COL!$B$2:$B$103,MATCH($B19,BMWP_COL!$A$2:$A$103,0)),"No aplica") -> 2 | D19: 25 | E19: 237 | F19: 277
A20: Diptera | B20: Culicidae | C20: =IFERROR(INDEX(BMWP_COL!$B$2:$B$103,MATCH($B20,BMWP_COL!$A$2:$A$103,0)),"No aplica") -> 2 | D20: 0 | E20: 0 | F20: 51
A21: Diptera | B21: Dixidae | C21: =IFERROR(INDEX(BMWP_COL!$B$2:$B$103,MATCH($B21,BMWP_COL!$A$2:$A$103,0)),"No aplica") -> 7 | D21: 0 | E21: 0 | F21: 9
... A59: Trombidiformes | B59: Limnesiidae | C59: =IFERROR(INDEX(BMWP_COL!$B$2:$B$103,MATCH($B59,BMWP_COL!$A$2:$A$103,0)),"No aplica") -> 5 | D59: 0 | E59: 1 | F59: 1
A60: Total tramo | D60: =SUM(D10:D59) -> 556 | E60: =SUM(E10:E59) -> 1234 | F60: =SUM(F10:F59) -> 3480
A62: 2. Abundancia por género, grupo funcional y tramo (hoja "Macroinv.", ambas campañas)
A64: Género | B64: Grupo funcional | C64: Bajo | D64: Medio | E64: Alto
A65: Americabaetis | B65: CG | C65: 82 | D65: 71 | E65: 327
A66: Anacroneuria | B66: Pr | C66: 26 | D66: 24 | E66: 219
A67: Anchytarsus | B67: Sh-Dt | C67: 0 | D67: 11 | E67: 100
A68: Argia | B68: Pr | C68: 2 | D68: 1 | E68: 2
A69: Atanatolica | B69: CG | C69: 6 | D69: 8 | E69: 211
A70: Atya | B70: CG | C70: 268 | D70: 1 | E70: 6
A71: Baetodes | B71: Ras | C71: 2 | D71: 91 | E71: 430
A72: Bezzia | B72: Pr | C72: 1 | D72: 14 | E72: 6
A73: Brechmorhoga | B73: Pr | C73: 0 | D73: 1 | E73: 6
A74: Cabecar | B74: CG | C74: 0 | D74: 1 | E74: 0
A75: Camelobaetidius | B75: Ras | C75: 0 | D75: 5 | E75: 35
A76: Chimarra | B76: Ft | C76: 0 | D76: 2 | E76: 13
... A141: Tricorythodes | B141: CG | C141: 21 | D141: 39 | E141: 64
A142: Total tramo | C142: =SUM(C65:C141) -> 556 | D142: =SUM(D65:D141) -> 1234 | E142: =SUM(E65:E141) -> 3480
A144: 3. Métricas del IIBMacroin — Tabla 23 de Pinilla (2008) + métricas calculada de los datos propios
A146: Métricas | B146: Código | C146: Bajo | D146: Medio | E146: Alto | F146: Tendendia ante perturbación
A147: Riqueza (Familias) | B147: TT | C147: =COUNTIF(D10:D59,">0") -> 27 | D147: =COUNTIF(E10:E59,">0") -> 32 | E147: =COUNTIF(F10:F59,">0") -> 46 | F147: Disminuye
A148: Riqueza de EPT (Familias) | B148: EPTR | C148: {=SUM(COUNTIFS($A$10:$A$59,{"Trichoptera";"Ephemeroptera";"Plecoptera"},D10:D59,">0"))} -> 8 | D148: {=SUM(COUNTIFS($A$10:$A$59,{"Trichoptera";"Ephemeroptera";"Plecoptera"},E10:E59,">0"))} -> 9 | E148: {=SUM(COUNTIFS($A$10:$A$59,{"Trichoptera";"Ephemeroptera";"Plecoptera"},F10:F59,">0"))} -> 13 | F148: Disminuye
A149: Riqueza de taxones únicos | B149: Singletons | C149: =COUNTIF(C65:C141,"1") -> 13 | D149: =COUNTIF(D65:D141,"1") -> 17 | E149: =COUNTIF(E65:E141,"1") -> 11
...

Sheet IIBPeces
A1: IIB Peces — Métricas de Comunidad Ictiológica Neotropical
A3: Nota metodológica
A4: Referentes bibliográficos: Pinto y Araujo (2007). Se agruparon ambas campañas de muestreo (nov-dic 2024 y may 2025). Se seleccionaron 7 métricas (Ab, TT, Cat, Sen, %Herb; %Omn y %Cat) y bibliográficamente se definió la tendencia de la métrica ante la perturbación en el ecosistema.
A6: 1. Abundancia y atributos por género y tramo (hoja "Peces", ambas campañas)
F8: Abundancia tramo
A9: Familia | B9: Género | C9: Hábito migratorio | D9: Tolerancia | E9: Gremio trófico | F9: Bajo | G9: Medio | H9: Alto
A10: Cichlidae | B10: Andinoacara | C10: Estacionario | D10: Tolerante | E10: Omnívoro | F10: 6 | G10: 0 | H10: 0
A11: Eleotridae | B11: Eleotris | C11: Catádromo | D11: Tolerante | E11: Carnívoro | F11: 6 | G11: 0 | H11: 0
A12: Eleotridae | B12: Gobiomorus | C12: Catádromo | D12: Tolerante | E12: Omnívoro | F12: 3 | G12: 0 | H12: 0
A13: Gobiidae | B13: Sicydium | C13: Catádromo | D13: Sensible | E13: Herbívoro | F13: 132 | G13: 90 | H13: 30
A14: Mugilidae | B14: Dajaus | C14: Catádromo | D14: Sensible | E14: Omnívoro | F14: 50 | G14: 33 | H14: 0
A15: Poeciliidae | B15: Poecilia | C15: Estacionario | D15: Tolerante | E15: Herbívoro | F15: 15 | G15: 0 | H15: 0
A16: Stevardiidae | B16: Hemibrycon | C16: Estacionario | D16: Sensible | E16: Omnívoro | F16: 9 | G16: 86 | H16: 0
A17: Trichomycteridae | B17: Trichomycterus | C17: Estacionario | D17: Tolerante | E17: Omnívoro | F17: 0 | G17: 0 | H17: 5
A20: 2. Métricas del IIBPeces por tramo
A22: Métrica | B22: Código | C22: Bajo | D22: Medio | E22: Alto | F22: Tendencia ante perturbación
A23: Abundancia | B23: Ab | C23: =SUM(F10:F17) -> 221 | D23: =SUM(G10:G17) -> 209 | E23: =SUM(H10:H17) -> 35 | F23: Decrece
A24: Riqueza (Familias) | B24: TT | C24: =COUNTIF(F10:F17,">0") -> 7 | D24: =COUNTIF(G10:G17,">0") -> 3 | E24: =COUNTIF(H10:H17,">0") -> 2 | F24: Decrece
A25: Riqueza Catádromos (Flias) | B25: Cat | C25: =COUNTIFS($C$10:$C$17,"Catádromo",F10:F17,">0") -> 4 | D25: =COUNTIFS($C$10:$C$17,"Catádromo",G10:G17,">0") -> 2 | E25: =COUNTIFS($C$10:$C$17,"Catádromo",H10:H17,">0") -> 1 | F25: Decrece
A26: Riqueza sensibles (Flias) | B26: Sen | C26: =COUNTIFS($D$10:$D$17,"Sensible",F10:F17,">0") -> 3 | D26: =COUNTIFS($D$10:$D$17,"Sensible",G10:G17,">0") -> 3 | E26: =COUNTIFS($D$10:$D$17,"Sensible",H10:H17,">0") -> 1 | F26: Decrece
A27: %Herbívoros | B27: %Herb | C27: =(SUMIFS(F10:F17,$E$10:$E$17,"Herbívoro")/C$23)*100 -> 66.515837 | D27: =(SUMIFS(G10:G17,$E$10:$E$17,"Herbívoro")/D$23)*100 -> 43.062201 | E27: =(SUMIFS(H10:H17,$E$10:$E$17,"Herbívoro")/E$23)*100 -> 85.714286 | F27: Decrece
A28: %Omnívoros | B28: %Omn | C28: =(SUMIFS(F10:F17,$E$10:$E$17,"Omnívoro")/C$23)*100 -> 30.769231 | D28: =(SUMIFS(G10:G17,$E$10:$E$17,"Omnívoro")/D$23)*100 -> 56.937799 | E28: =(SUMIFS(H10:H17,$E$10:$E$17,"Omnívoro")/E$23)*100 -> 14.285714 | F28: Aumenta
A29: % Abundancia catádromos | B29: %Cat | C29: =(SUMIFS(F10:F17,$C$10:$C$17,"Catádromo")/C$23)*100 -> 86.425339 | D29: =(SUMIFS(G10:G17,$C$10:$C$17,"Catádromo")/D$23)*100 -> 58.851675 | E29: =(SUMIFS(H10:H17,$C$10:$C$17,"Catádromo")/E$23)*100 -> 85.714286 | F29: Decrece
A32: 3. Puntaje por métrica
A34: No existe tabla de puntaje absoluto publicada para estas 7 métricas (ni en Pinilla 2008 Tabla 28 -que exige variables no disponibles como Libro Rojo, línea base histórica o anormalidades-, ni en Pinto y Araujo 2007/Carvalho y Gerson 2007 -que usan min-max entre sus propios sitios muestreados, ver nota A36 abajo-). Se revierte la estandarización min-max entre los 3 tramos (versión anterior) a una transformación ABSOLUTA, con dos convenciones distintas según el tipo de métrica, ambas marcadas como supuesto propio (Regla de rigor #4):
A36: (a) Métricas de % de composición (%Herb, %Omn, %Cat): se usa el corte de terciles 33% / 67% que Pinilla et al. (2008, Tabla 28) ya usa para sus propias métricas porcentuales N y PN, dentro del mismo marco metodológico de peces del proyecto — no es literal para %Herb/%Omn/%Cat, pero reutiliza la única convención absoluta de corte que existe en la bibliografía de peces de este proyecto.
A38: (b) Métricas de riqueza (TT, Cat, Sen): se reescalan sobre el total de familias DOCUMENTADAS en el muestreo combinado (ambas campañas, hoja "Peces"), no sobre el mínimo/máximo de los 3 tramos — por eso sigue siendo "absoluto": el denominador no cambia si se agrega un tramo o una campaña nueva. Total de familias = 7; catádromas = 4 (Eleotridae, Gobiidae, Mugilidae); sensibles = 3 (Gobiidae, Mugilidae, Stevardiidae).
A39: Métrica que aumenta con el deterioro (menor valor = mejor estado): Puntaje = (Xmax − X) / (Xmax − Xmin)
A40: Abundancia (Ab) se excluye del promedio final: Carvalho y Gerson (2007) — la misma fuente "Pinto y Araujo (2007)"/"Teixeira & Araujo (2007)" ya citada para peces en este proyecto, ver prompt maestro — descartaron explícitamente el número total de individuos como métrica del IBI "porque no difirió significativamente entre las muestras, ni presentó correlación con el IBI". Se deja como dato descriptivo (fila 42), no puntuable.
A41: Métrica | B41: Código | C41: Puntaje Bajo | D41: Puntaje Medio | E41: Puntaje Alto
A42: Abundancia | B42: Ab | C42: No se califica (ver nota A40) | D42: No se califica (ver nota A40) | E42: No se califica (ver nota A40)
A43: Riqueza (Familias) | B43: TT | C43: =C24/7 -> 1 | D43: =D24/7 -> 0.42857143 | E43: =E24/7 -> 0.28571429
A44: Riqueza Catádromos (Flias) | B44: Cat | C44: =C25/4 -> 1 | D44: =D25/4 -> 0.5 | E44: =E25/4 -> 0.25
A45: Riqueza sensibles (Flias) | B45: Sen | C45: =C26/3 -> 1 | D45: =D26/3 -> 1 | E45: =E26/3 -> 0.33333333
A46: %Herbívoros | B46: %Herb | C46: =IF(C27>67,1,IF(C27>=33,0.6,0.2)) -> 0.6 | D46: =IF(D27>67,1,IF(D27>=33,0.6,0.2)) -> 0.6 | E46: =IF(E27>67,1,IF(E27>=33,0.6,0.2)) -> 1
A47: %Omnívoros | B47: %Omn | C47: =IF(C28>67,0.2,IF(C28>=33,0.6,1)) -> 1 | D47: =IF(D28>67,0.2,IF(D28>=33,0.6,1)) -> 0.6 | E47: =IF(E28>67,0.2,IF(E28>=33,0.6,1)) -> 1
A48: % Abundancia catádromos | B48: %Cat | C48: =IF(C29>67,1,IF(C29>=33,0.6,0.2)) -> 1 | D48: =IF(D29>67,1,IF(D29>=33,0.6,0.2)) -> 0.6 | E48: =IF(E29>67,1,IF(E29>=33,0.6,0.2)) -> 1
A52: 4. Cálculo del IIBPeces
